Workbook

Sheet Claude Log
A1: Turn # | B1: Date | C1: User Request | D1: Action Taken | E1: Details | F1: Outcome
A2: 1 | B2: 46323 | C2: 서브토탈(합계 행) 범위 누락 여부 점검 요청 | D2: 설문조사 DB 시트 B5:AB5의 SUM 범위를 각 문항 데이터(6~16행)와 대조 (읽기 전용) | E2: SUBTOTAL 함수는 없고 5행 SUM이 합계 역할. C~E열은 6~11/15/13행까지, F~AB열은 6~16행까지 합산. 각 열의 마지막 응답값 행이 합계 범위 끝 이내인지 확인 | F2: 누락 없음. 수정 없음
A3: 2 | B3: 46323 | C3: 합계가 SUM이 아니라 COUNTIF라고 정정, COUNTIF 범위 누락 재점검 요청 | D3: 설문조사 DB 시트 B6:AB16의 COUNTIF 160개 범위를 응답 데이터 끝 행과 대조 (읽기 전용) | E3: 응답 데이터 17~540행(U열 530행). COUNTIF 범위는 17행 시작, 끝 행 565~708로 모두 540행 이상. 집계 열과 A열 조건 셀 참조 정상. V열은 =U+T 수식. 끝 행이 열마다 달라 통일 권장 | F3: 누락 없음. 수정 없음. 끝 행 통일(예: 687행)은 사용자 확인 대기
A4: 3 | B4: 46323 | C4: COUNTIF 끝 행이 문항별로 달라 9999로 통일 요청 | D4: 설문조사 DB 시트 B6:AB16의 COUNTIF 160개 끝 행을 9999로 변경 | E4: 예: =COUNTIF($C$17:$C$9999,$A6). 시작 행(17)·집계 열·조건 셀은 그대로. V열 =U+T 수식은 변경 없음 | F4: 160개 모두 변경 확인, 오류 없음. 5행 합계(B~F열 497/506/512/502/504) 변경 전과 동일
A5: 4 | B5: 46323 | C5: 설문조사 DB AC열(건의사항)을 설문조사 결과 시트 선택 영역(A1170:I1184)에 정리 요청 | D5: AC열 응답 42건을 11개 주제로 분류해 설문조사 결과!A1170:A1180에 요약, I열에 건수·DB 행번호 기재 | E5: DB AC17:AC576의 비어있지 않은 응답 42건 기준. 관련부서(G열)는 근거 없어 비워둠. 복합 의견은 주된 주제 1곳에만 배정 | F5: 완료. 사용자 확인 대기(분류 기준 조정 가능)

Sheet 설문조사 결과
A1: 2026년도 옥천군 예산편성 설문조사결과
A2: Ⅰ. 기본사항
C8: 응답항목 | D8: 응답수 | E8: 비율
C9: 합 계 | D9: ='설문조사 DB'!B5 -> 497 | E9: ='설문조사 DB'!B5/'설문조사 DB'!$B$5 -> 1
C10: ① 남 | D10: ='설문조사 DB'!B6 -> 246 | E10: ='설문조사 DB'!B6/'설문조사 DB'!$B$5 -> 0.49496982
C11: ② 여 | D11: ='설문조사 DB'!B7 -> 251 | E11: ='설문조사 DB'!B7/'설문조사 DB'!$B$5 -> 0.50503018
C46: 응답항목 | D46: 응답수 | E46: 비율
C47: 합 계 | D47: ='설문조사 DB'!C5 -> 506 | E47: ='설문조사 DB'!C5/'설문조사 DB'!$C$5 -> 1
C48: ① 19세 이하 | D48: ='설문조사 DB'!C6 -> 1 | E48: ='설문조사 DB'!C6/'설문조사 DB'!$C$5 -> 0.0019762846
C49: ② 20대 | D49: ='설문조사 DB'!C7 -> 23 | E49: ='설문조사 DB'!C7/'설문조사 DB'!$C$5 -> 0.045454545
C50: ③ 30대 | D50: ='설문조사 DB'!C8 -> 53 | E50: ='설문조사 DB'!C8/'설문조사 DB'!$C$5 -> 0.10474308
C51: ④ 40대 | D51: ='설문조사 DB'!C9 -> 73 | E51: ='설문조사 DB'!C9/'설문조사 DB'!$C$5 -> 0.14426877
C52: ⑤ 50대 | D52: ='설문조사 DB'!C10 -> 106 | E52: ='설문조사 DB'!C10/'설문조사 DB'!$C$5 -> 0.20948617
C53: ⑥ 60대 이상 | D53: ='설문조사 DB'!C11 -> 250 | E53: ='설문조사 DB'!C11/'설문조사 DB'!$C$5 -> 0.49407115
C91: 응답항목 | D91: 응답수 | E91: 비율
C92: 합 계 | D92: ='설문조사 DB'!D5 -> 512 | E92: ='설문조사 DB'!D5/'설문조사 DB'!$D$5 -> 1
C93: ① 옥천읍 | D93: ='설문조사 DB'!D6 -> 151 | E93: ='설문조사 DB'!D6/'설문조사 DB'!$D$5 -> 0.29492188
C94: ② 동이면 | D94: ='설문조사 DB'!D7 -> 38 | E94: ='설문조사 DB'!D7/'설문조사 DB'!$D$5 -> 0.07421875
C95: ③ 안남면 | D95: ='설문조사 DB'!D8 -> 39 | E95: ='설문조사 DB'!D8/'설문조사 DB'!$D$5 -> 0.076171875
C96: ④ 안내면 | D96: ='설문조사 DB'!D9 -> 52 | E96: ='설문조사 DB'!D9/'설문조사 DB'!$D$5 -> 0.1015625
C97: ⑤ 청성면 | D97: ='설문조사 DB'!D10 -> 38 | E97: ='설문조사 DB'!D10/'설문조사 DB'!$D$5 -> 0.07421875
C98: ⑥ 청산면 | D98: ='설문조사 DB'!D11 -> 41 | E98: ='설문조사 DB'!D11/'설문조사 DB'!$D$5 -> 0.080078125
C99: ⑦ 이원면 | D99: ='설문조사 DB'!D12 -> 41 | E99: ='설문조사 DB'!D12/'설문조사 DB'!$D$5 -> 0.080078125
C100: ⑧ 군서면 | D100: ='설문조사 DB'!D13 -> 40 | E100: ='설문조사 DB'!D13/'설문조사 DB'!$D$5 -> 0.078125
C101: ⑨ 군북면 | D101: ='설문조사 DB'!D14 -> 47 | E101: ='설문조사 DB'!D14/'설문조사 DB'!$D$5 -> 0.091796875
C102: ⑩ 관 외 | D102: ='설문조사 DB'!D15 -> 25 | E102: ='설문조사 DB'!D15/'설문조사 DB'!$D$5 -> 0.048828125
C139: 응답항목 | D139: 응답수 | E139: 비율
C140: 합 계 | D140: ='설문조사 DB'!E5 -> 502 | E140: ='설문조사 DB'!E5/'설문조사 DB'!$E$5 -> 1
C141: ① 농∙축∙어업 | D141: ='설문조사 DB'!E6 -> 209 | E141: ='설문조사 DB'!E6/'설문조사 DB'!$E$5 -> 0.41633466
C142: ② 가정주부 | D142: ='설문조사 DB'!E7 -> 66 | E142: ='설문조사 DB'!E7/'설문조사 DB'!$E$5 -> 0.1314741
C143: ③ 자영업 | D143: ='설문조사 DB'!E8 -> 70 | E143: ='설문조사 DB'!E8/'설문조사 DB'!$E$5 -> 0.13944223
C144: ④ 회사원 | D144: ='설문조사 DB'!E9 -> 33 | E144: ='설문조사 DB'!E9/'설문조사 DB'!$E$5 -> 0.065737052
C145: ⑤ 전문직 | D145: ='설문조사 DB'!E10 -> 17 | E145: ='설문조사 DB'!E10/'설문조사 DB'!$E$5 -> 0.033864542
C146: ⑥ 학생 | D146: ='설문조사 DB'!E11 -> 6 | E146: ='설문조사 DB'!E11/'설문조사 DB'!$E$5 -> 0.011952191
C147: ⑦ 공무원 | D147: ='설문조사 DB'!E12 -> 48 | E147: ='설문조사 DB'!E12/'설문조사 DB'!$E$5 -> 0.09561753
C148: ⑧ 기 타 | D148: ='설문조사 DB'!E13 -> 53 | E148: ='설문조사 DB'!E13/'설문조사 DB'!$E$5 -> 0.10557769
A182: Ⅱ. 재정운용
C192: 응답항목 | D192: 응답수 | E192: 비율
C193: 합 계 | D193: ='설문조사 DB'!F5 -> 504 | E193: ='설문조사 DB'!F5/'설문조사 DB'!F5 -> 1
C194: ① 경기활성화 | D194: ='설문조사 DB'!F6 -> 222 | E194: ='설문조사 DB'!F6/'설문조사 DB'!$F$5 -> 0.44047619
...

Sheet 설문조사 DB
A1: 2025년도 옥천군 예산편성 설문조사 DB
A3: 문항 및 응답 | B3: Ⅰ. 기본사항 | F3: Ⅱ. 재정운용 | AC3: Ⅲ.건의사항 및 제안사항 | AD3: 비고
B4: Q1 | C4: Q2 | D4: Q3 | E4: Q4 | F4: Q1 | G4: Q2 | H4: Q3 | I4: Q4 | J4: Q5 | K4: Q6 | L4: Q7 | M4: Q8 | N4: Q9 | O4: Q10 | P4: Q11 | Q4: Q12 | R4: Q13 | S4: Q14 | T4: Q15-1 | U4: Q15-2 | V4: Q15 | W4: Q16 | X4: Q17 | Y4: Q18 | Z4: Q19 | AA4: Q20 | AB4: Q21
A5: 합계 | B5: =SUM(B6:B16) -> 497 | C5: =SUM(C6:C11) -> 506 | D5: =SUM(D6:D15) -> 512 | E5: =SUM(E6:E13) -> 502 | F5: =SUM(F6:F16) -> 504 | G5: =SUM(G6:G16) -> 510 | H5: =SUM(H6:H16) -> 496 | I5: =SUM(I6:I16) -> 471 | J5: =SUM(J6:J16) -> 503 | K5: =SUM(K6:K16) -> 503 | L5: =SUM(L6:L16) -> 506 | M5: =SUM(M6:M16) -> 501 | ... AB5: =SUM(AB6:AB16) -> 497
A6: 1 | B6: =COUNTIF($B$17:$B$9999,$A6) -> 246 | C6: =COUNTIF($C$17:$C$9999,$A6) -> 1 | D6: =COUNTIF($D$17:$D$9999,$A6) -> 151 | E6: =COUNTIF($E$17:$E$9999,$A6) -> 209 | F6: =COUNTIF($F$17:$F$9999,$A6) -> 222 | G6: =COUNTIF($G$17:$G$9999,$A6) -> 35 | H6: =COUNTIF($H$17:$H$9999,$A6) -> 322 | I6: =COUNTIF($I$17:$I$9999,$A6) -> 55 | J6: =COUNTIF($J$17:$J$9999,$A6) -> 88 | K6: =COUNTIF($K$17:$K$9999,$A6) -> 86 | L6: =COUNTIF($L$17:$L$9999,$A6) -> 190 | M6: =COUNTIF($M$17:$M$9999,$A6) -> 77 | N6: =COUNTIF($N$17:$N$9999,$A6) -> 110 | O6: =COUNTIF($O$17:$O$9999,$A6) -> 92 | P6: =COUNTIF($P$17:$P$9999,$A6) -> 251 | Q6: =COUNTIF($Q$17:$Q$9999,$A6) -> 97 | R6: =COUNTIF($R$17:$R$9999,$A6) -> 58 | S6: =COUNTIF($S$17:$S$9999,$A6) -> 101 | T6: =COUNTIF($T$17:$T$9999,$A6) -> 80 | U6: =COUNTIF($U$17:$U$9999,$A6) -> 0 | V6: =U6+T6 -> 80 | W6: =COUNTIF($W$17:$W$9999,$A6) -> 154 | X6: =COUNTIF($X$17:$X$9999,$A6) -> 65 | Y6: =COUNTIF($Y$17:$Y$9999,$A6) -> 67 | Z6: =COUNTIF($Z$17:$Z$9999,$A6) -> 171 | AA6: =COUNTIF($AA$17:$AA$9999,$A6) -> 70 | AB6: =COUNTIF($AB$17:$AB$9999,$A6) -> 66
A7: 2 | B7: =COUNTIF($B$17:$B$9999,$A7) -> 251 | C7: =COUNTIF($C$17:$C$9999,$A7) -> 23 | D7: =COUNTIF($D$17:$D$9999,$A7) -> 38 | E7: =COUNTIF($E$17:$E$9999,$A7) -> 66 | F7: =COUNTIF($F$17:$F$9999,$A7) -> 146 | G7: =COUNTIF($G$17:$G$9999,$A7) -> 161 | H7: =COUNTIF($H$17:$H$9999,$A7) -> 78 | I7: =COUNTIF($I$17:$I$9999,$A7) -> 44 | J7: =COUNTIF($J$17:$J$9999,$A7) -> 196 | K7: =COUNTIF($K$17:$K$9999,$A7) -> 54 | L7: =COUNTIF($L$17:$L$9999,$A7) -> 106 | M7: =COUNTIF($M$17:$M$9999,$A7) -> 184 | N7: =COUNTIF($N$17:$N$9999,$A7) -> 137 | O7: =COUNTIF($O$17:$O$9999,$A7) -> 41 | P7: =COUNTIF($P$17:$P$9999,$A7) -> 146 | Q7: =COUNTIF($Q$17:$Q$9999,$A7) -> 81 | R7: =COUNTIF($R$17:$R$9999,$A7) -> 142 | S7: =COUNTIF($S$17:$S$9999,$A7) -> 139 | T7: =COUNTIF($T$17:$T$9999,$A7) -> 117 | U7: =COUNTIF($U$17:$U$9999,$A7) -> 10 | V7: =U7+T7 -> 127 | W7: =COUNTIF($W$17:$W$9999,$A7) -> 171 | X7: =COUNTIF($X$17:$X$9999,$A7) -> 128 | Y7: =COUNTIF($Y$17:$Y$9999,$A7) -> 109 | Z7: =COUNTIF($Z$17:$Z$9999,$A7) -> 132 | AA7: =COUNTIF($AA$17:$AA$9999,$A7) -> 161 | AB7: =COUNTIF($AB$17:$AB$9999,$A7) -> 155
A8: 3 | C8: =COUNTIF($C$17:$C$9999,$A8) -> 53 | D8: =COUNTIF($D$17:$D$9999,$A8) -> 39 | E8: =COUNTIF($E$17:$E$9999,$A8) -> 70 | F8: =COUNTIF($F$17:$F$9999,$A8) -> 102 | G8: =COUNTIF($G$17:$G$9999,$A8) -> 210 | H8: =COUNTIF($H$17:$H$9999,$A8) -> 67 | I8: =COUNTIF($I$17:$I$9999,$A8) -> 83 | J8: =COUNTIF($J$17:$J$9999,$A8) -> 74 | K8: =COUNTIF($K$17:$K$9999,$A8) -> 43 | L8: =COUNTIF($L$17:$L$9999,$A8) -> 130 | M8: =COUNTIF($M$17:$M$9999,$A8) -> 116 | N8: =COUNTIF($N$17:$N$9999,$A8) -> 50 | O8: =COUNTIF($O$17:$O$9999,$A8) -> 86 | P8: =COUNTIF($P$17:$P$9999,$A8) -> 69 | Q8: =COUNTIF($Q$17:$Q$9999,$A8) -> 44 | R8: =COUNTIF($R$17:$R$9999,$A8) -> 77 | S8: =COUNTIF($S$17:$S$9999,$A8) -> 149 | T8: =COUNTIF($T$17:$T$9999,$A8) -> 115 | U8: =COUNTIF($U$17:$U$9999,$A8) -> 31 | V8: =U8+T8 -> 146 | W8: =COUNTIF($W$17:$W$9999,$A8) -> 175 | X8: =COUNTIF($X$17:$X$9999,$A8) -> 180 | Y8: =COUNTIF($Y$17:$Y$9999,$A8) -> 168 | Z8: =COUNTIF($Z$17:$Z$9999,$A8) -> 98 | AA8: =COUNTIF($AA$17:$AA$9999,$A8) -> 113 | AB8: =COUNTIF($AB$17:$AB$9999,$A8) -> 103
A9: 4 | C9: =COUNTIF($C$17:$C$9999,$A9) -> 73 | D9: =COUNTIF($D$17:$D$9999,$A9) -> 52 | E9: =COUNTIF($E$17:$E$9999,$A9) -> 33 | F9: =COUNTIF($F$17:$F$9999,$A9) -> 26 | G9: =COUNTIF($G$17:$G$9999,$A9) -> 35 | H9: =COUNTIF($H$17:$H$9999,$A9) -> 29 | I9: =COUNTIF($I$17:$I$9999,$A9) -> 60 | J9: =COUNTIF($J$17:$J$9999,$A9) -> 134 | K9: =COUNTIF($K$17:$K$9999,$A9) -> 144 | L9: =COUNTIF($L$17:$L$9999,$A9) -> 46 | M9: =COUNTIF($M$17:$M$9999,$A9) -> 80 | N9: =COUNTIF($N$17:$N$9999,$A9) -> 90 | O9: =COUNTIF($O$17:$O$9999,$A9) -> 142 | P9: =COUNTIF($P$17:$P$9999,$A9) -> 37 | Q9: =COUNTIF($Q$17:$Q$9999,$A9) -> 52 | R9: =COUNTIF($R$17:$R$9999,$A9) -> 149 | S9: =COUNTIF($S$17:$S$9999,$A9) -> 107 | T9: =COUNTIF($T$17:$T$9999,$A9) -> 58 | U9: =COUNTIF($U$17:$U$9999,$A9) -> 24 | V9: =U9+T9 -> 82 | X9: =COUNTIF($X$17:$X$9999,$A9) -> 85 | Y9: =COUNTIF($Y$17:$Y$9999,$A9) -> 92 | Z9: =COUNTIF($Z$17:$Z$9999,$A9) -> 91 | AA9: =COUNTIF($AA$17:$AA$9999,$A9) -> 57 | AB9: =COUNTIF($AB$17:$AB$9999,$A9) -> 65
A10: 5 | C10: =COUNTIF($C$17:$C$9999,$A10) -> 106 | D10: =COUNTIF($D$17:$D$9999,$A10) -> 38 | E10: =COUNTIF($E$17:$E$9999,$A10) -> 17 | F10: =COUNTIF($F$17:$F$9999,$A10) -> 8 | G10: =COUNTIF($G$17:$G$9999,$A10) -> 69 | I10: =COUNTIF($I$17:$I$9999,$A10) -> 22 | J10: =COUNTIF($J$17:$J$9999,$A10) -> 8 | K10: =COUNTIF($K$17:$K$9999,$A10) -> 169 | L10: =COUNTIF($L$17:$L$9999,$A10) -> 33 | M10: =COUNTIF($M$17:$M$9999,$A10) -> 42 | N10: =COUNTIF($N$17:$N$9999,$A10) -> 116 | O10: =COUNTIF($O$17:$O$9999,$A10) -> 63 | P10: =COUNTIF($P$17:$P$9999,$A10) -> 3 | Q10: =COUNTIF($Q$17:$Q$9999,$A10) -> 68 | R10: =COUNTIF($R$17:$R$9999,$A10) -> 71 | S10: =COUNTIF($S$17:$S$9999,$A10) -> 1 | T10: =COUNTIF($T$17:$T$9999,$A10) -> 47 | U10: =COUNTIF($U$17:$U$9999,$A10) -> 43 | V10: =U10+T10 -> 90 | X10: =COUNTIF($X$17:$X$9999,$A10) -> 39 | Y10: =COUNTIF($Y$17:$Y$9999,$A10) -> 61 | Z10: =COUNTIF($Z$17:$Z$9999,$A10) -> 1 | AA10: =COUNTIF($AA$17:$AA$9999,$A10) -> 85 | AB10: =COUNTIF($AB$17:$AB$9999,$A10) -> 53
A11: 6 | C11: =COUNTIF($C$17:$C$9999,$A11) -> 250 | D11: =COUNTIF($D$17:$D$9999,$A11) -> 41 | E11: =COUNTIF($E$17:$E$9999,$A11) -> 6 | I11: =COUNTIF($I$17:$I$9999,$A11) -> 55 | J11: =COUNTIF($J$17:$J$9999,$A11) -> 3 | K11: =COUNTIF($K$17:$K$9999,$A11) -> 7 | L11: =COUNTIF($L$17:$L$9999,$A11) -> 1 | M11: =COUNTIF($M$17:$M$9999,$A11) -> 2 | N11: =COUNTIF($N$17:$N$9999,$A11) -> 2 | O11: =COUNTIF($O$17:$O$9999,$A11) -> 54 | Q11: =COUNTIF($Q$17:$Q$9999,$A11) -> 36 | R11: =COUNTIF($R$17:$R$9999,$A11) -> 0 | T11: =COUNTIF($T$17:$T$9999,$A11) -> 36 | U11: =COUNTIF($U$17:$U$9999,$A11) -> 30 | V11: =U11+T11 -> 66 | AA11: =COUNTIF($AA$17:$AA$9999,$A11) -> 4 | AB11: =COUNTIF($AB$17:$AB$9999,$A11) -> 55
A12: 7 | D12: =COUNTIF($D$17:$D$9999,$A12) -> 41 | E12: =COUNTIF($E$17:$E$9999,$A12) -> 48 | I12: =COUNTIF($I$17:$I$9999,$A12) -> 14 | O12: =COUNTIF($O$17:$O$9999,$A12) -> 22 | Q12: =COUNTIF($Q$17:$Q$9999,$A12) -> 76 | T12: =COUNTIF($T$17:$T$9999,$A12) -> 29 | U12: =COUNTIF($U$17:$U$9999,$A12) -> 54 | V12: =U12+T12 -> 83
A13: 8 | D13: =COUNTIF($D$17:$D$9999,$A13) -> 40 | E13: =COUNTIF($E$17:$E$9999,$A13) -> 53 | I13: =COUNTIF($I$17:$I$9999,$A13) -> 49 | O13: =COUNTIF($O$17:$O$9999,$A13) -> 3 | Q13: =COUNTIF($Q$17:$Q$9999,$A13) -> 38 | T13: =COUNTIF($T$17:$T$9999,$A13) -> 18 | U13: =COUNTIF($U$17:$U$9999,$A13) -> 55 | V13: =U13+T13 -> 73
A14: 9 | D14: =COUNTIF($D$17:$D$9999,$A14) -> 47 | I14: =COUNTIF($I$17:$I$9999,$A14) -> 66 | Q14: =COUNTIF($Q$17:$Q$9999,$A14) -> 5
A15: 10 | D15: =COUNTIF($D$17:$D$9999,$A15) -> 25 | I15: =COUNTIF($I$17:$I$9999,$A15) -> 23 | Q15: =COUNTIF($Q$17:$Q$9999,$A15) -> 2
A16: 11
A17: 1 | B17: 1 | C17: 3 | D17: 1 | E17: 4 | F17: 1 | G17: 3 | H17: 1 | I17: 9 | J17: 1 | K17: 5 | L17: 3 | M17: 2 | N17: 2 | O17: 1 | P17: 2 | Q17: 5 | R17: 2 | S17: 3 | T17: 2 | W17: 1 | X17: 3 | Y17: 3 | Z17: 4 | AA17: 1 | AB17: 2 | AD17: 옥천 | AE17: 1
A18: 2 | C18: 5 | D18: 1 | E18: 3 | F18: 2 | G18: 3 | H18: 2 | I18: 3 | J18: 2 | K18: 5 | L18: 3 | M18: 2 | N18: 5 | O18: 1 | P18: 2 | Q18: 1 | R18: 2 | S18: 4 | T18: 8 | W18: 3 | X18: 3 | Y18: 3 | Z18: 4 | AA18: 3 | AB18: 3 | AD18: 옥천 | AE18: 2
A19: 3 | B19: 1 | C19: 4 | D19: 1 | E19: 3 | F19: 1 | G19: 1 | H19: 1 | I19: 4 | J19: 2 | K19: 4 | L19: 1 | M19: 1 | N19: 5 | O19: 1 | P19: 2 | Q19: 1 | R19: 5 | S19: 2 | T19: 3 | W19: 3 | X19: 2 | Y19: 2 | Z19: 4 | AA19: 1 | AB19: 3 | AD19: 옥천 | AE19: 3
A20: 4 | B20: 1 | C20: 4 | D20: 1 | E20: 7 | F20: 1 | G20: 3 | H20: 1 | I20: 7 | J20: 2 | K20: 2 | L20: 1 | M20: 4 | N20: 1 | O20: 5 | P20: 2 | Q20: 8 | R20: 2 | S20: 4 | T20: 7 | W20: 1 | X20: 2 | Y20: 5 | Z20: 3 | AA20: 2 | AB20: 3 | AD20: 옥천 | AE20: 4
A21: 5 | B21: 1 | C21: 5 | D21: 1 | E21: 3 | F21: 1 | G21: 2 | H21: 3 | I21: 1 | J21: 1 | K21: 5 | L21: 1 | M21: 1 | N21: 5 | O21: 1 | P21: 2 | Q21: 1 | R21: 2 | S21: 4 | T21: 2 | U21: 3 | W21: 1 | X21: 1 | Y21: 2 | Z21: 2 | AA21: 2 | AB21: 2 | AD21: 옥천 | AE21: 5
A22: 6 | B22: 1 | C22: 5 | D22: 1 | E22: 8 | F22: 1 | G22: 3 | H22: 1 | I22: 4 | J22: 2 | K22: 5 | L22: 3 | M22: 3 | N22: 5 | O22: 6 | P22: 1 | Q22: 6 | R22: 2 | S22: 4 | T22: 2 | U22: 3 | W22: 1 | X22: 1 | Y22: 1 | Z22: 3 | AA22: 5 | AB22: 3 | AD22: 옥천 | AE22: 6
A23: 7 | B23: 1 | C23: 4 | D23: 1 | E23: 4 | F23: 3 | G23: 2 | H23: 1 | I23: 2 | J23: 2 | K23: 1 | L23: 2 | M23: 4 | N23: 5 | O23: 5 | P23: 2 | Q23: 5 | R23: 4 | S23: 4 | T23: 1 | U23: 7 | W23: 3 | X23: 5 | Y23: 5 | Z23: 3 | AA23: 2 | AB23: 3 | AD23: 옥천 | AE23: 7
A24: 8 | B24: 1 | C24: 4 | D24: 1 | E24: 5 | F24: 1 | G24: 2 | H24: 1 | I24: 2 | J24: 2 | K24: 1 | L24: 3 | M24: 4 | N24: 5 | O24: 4 | P24: 1 | Q24: 5 | R24: 5 | S24: 4 | T24: 1 | U24: 7 | W24: 3 | X24: 5 | Y24: 5 | Z24: 3 | AA24: 2 | AB24: 2 | AD24: 옥천 | AE24: 8
A25: 9 | B25: 1 | C25: 5 | D25: 1 | E25: 5 | F25: 3 | G25: 2 | H25: 2 | I25: 3 | J25: 4 | K25: 4 | L25: 1 | M25: 4 | N25: 4 | O25: 7 | P25: 1 | Q25: 1 | R25: 1 | S25: 4 | T25: 2 | U25: 7 | W25: 2 | X25: 3 | Y25: 3 | Z25: 4 | AA25: 2 | AB25: 2 | AC25: 권역별로 선택과 집중을 하면 좋겠습니다 | AD25: 옥천 | AE25: 9
A26: 10 | B26: 1 | C26: 4 | D26: 1 | E26: 3 | F26: 1 | G26: 3 | H26: 1 | I26: 8 | J26: 2 | K26: 1 | L26: 3 | M26: 2 | N26: 5 | O26: 2 | P26: 3 | Q26: 4 | R26: 5 | S26: 4 | T26: 6 | W26: 1 | X26: 2 | Y26: 2 | Z26: 3 | AA26: 3 | AB26: 2 | AD26: 옥천 | AE26: 10
A27: 11 | B27: 1 | C27: 4 | D27: 1 | E27: 3 | F27: 3 | G27: 2 | H27: 3 | I27: 2 | J27: 2 | K27: 3 | L27: 3 | M27: 3 | N27: 4 | O27: 1 | P27: 2 | Q27: 4 | R27: 2 | S27: 3 | T27: 3 | W27: 2 | X27: 2 | Y27: 2 | Z27: 2 | AA27: 3 | AB27: 2 | AD27: 옥천 | AE27: 11
A28: 12 | B28: 1 | C28: 4 | D28: 1 | E28: 5 | F28: 1 | G28: 3 | H28: 1 | I28: 10 | J28: 2 | K28: 5 | L28: 2 | M28: 4 | N28: 2 | O28: 6 | P28: 1 | Q28: 8 | R28: 2 | S28: 4 | T28: 2 | U28: 7 | W28: 2 | X28: 4 | Y28: 5 | Z28: 4 | AA28: 3 | AB28: 6 | AD28: 옥천 | AE28: 12
A29: 13 | B29: 2 | C29: 2 | D29: 1 | E29: 6 | F29: 2 | G29: 5 | H29: 1 | I29: 4 | J29: 2 | K29: 1 | L29: 5 | M29: 6 | N29: 3 | O29: 3 | P29: 1 | Q29: 2 | R29: 4 | S29: 3 | T29: 3 | U29: 5 | W29: 3 | X29: 3 | Y29: 4 | Z29: 3 | AA29: 4 | AB29: 3 | AC29: 영화관, 수영장 등 문화·예술 관련 시설 많이 지어주세요. | AD29: 옥천 | AE29: 13
A30: 14 | B30: 2 | C30: 2 | D30: 1 | E30: 8 | F30: 2 | G30: 2 | H30: 1 | I30: 4 | J30: 5 | K30: 5 | L30: 1 | M30: 4 | N30: 2 | O30: 6 | P30: 1 | Q30: 9 | R30: 4 | S30: 4 | T30: 5 | U30: 6 | W30: 1 | X30: 3 | Y30: 2 | Z30: 3 | AA30: 2 | AB30: 4 | AD30: 옥천 | AE30: 14
A31: 15 | B31: 1 | C31: 5 | D31: 1 | E31: 5 | F31: 1 | G31: 2 | H31: 1 | I31: 4 | J31: 3 | K31: 1 | L31: 3 | M31: 3 | N31: 4 | O31: 3 | P31: 1 | Q31: 8 | R31: 3 | S31: 4 | T31: 7 | W31: 1 | X31: 2 | Y31: 1 | Z31: 3 | AA31: 4 | AB31: 3 | AD31: 옥천 | AE31: 15
A32: 16 | B32: 2 | C32: 3 | D32: 1 | E32: 7 | F32: 2 | G32: 2 | H32: 1 | I32: 9 | J32: 4 | K32: 5 | L32: 1 | M32: 2 | N32: 2 | O32: 5 | P32: 1 | Q32: 1 | R32: 2 | S32: 3 | T32: 1 | U32: 2 | W32: 2 | X32: 4 | Y32: 4 | Z32: 1 | AA32: 3 | AB32: 6 | AD32: 옥천 | AE32: 16
A33: 17 | B33: 1 | C33: 2 | D33: 1 | E33: 8 | F33: 2 | G33: 5 | H33: 1 | I33: 3 | J33: 2 | K33: 2 | L33: 4 | M33: 4 | N33: 5 | O33: 1 | P33: 1 | Q33: 8 | R33: 4 | S33: 2 | T33: 4 | U33: 5 | W33: 3 | X33: 4 | Y33: 4 | Z33: 1 | AA33: 5 | AB33: 2 | AD33: 옥천 | AE33: 17
A34: 18 | B34: 2 | C34: 5 | D34: 1 | E34: 8 | F34: 2 | G34: 3 | H34: 3 | I34: 9 | J34: 4 | K34: 6 | L34: 1 | N34: 2 | O34: 7 | P34: 1 | Q34: 6 | R34: 2 | S34: 4 | T34: 2 | U34: 6 | X34: 4 | Y34: 4 | Z34: 2 | AA34: 2 | AB34: 2 | AC34: 재래시장 내 전기사용량을 줄여 경비 절감하고 태양열 에너지 재판매하여 양쪽 진출입 통로 등을 튼튼한 것으로 교체하면 어떨까요? 보안을 위해 늦은 시간까지 시장 전체에 사용하는 전기 양이 너무 많습니다. | AD34: 옥천 | AE34: 18
A35: 19 | B35: 2 | C35: 3 | D35: 1 | E35: 8 | F35: 1 | G35: 3 | H35: 1 | I35: 4 | J35: 2 | K35: 5 | L35: 1 | M35: 2 | N35: 5 | O35: 5 | P35: 3 | Q35: 5 | R35: 4 | S35: 1 | T35: 5 | W35: 2 | X35: 3 | Y35: 3 | Z35: 1 | AA35: 5 | AB35: 3 | AD35: 옥천 | AE35: 19
A36: 20 | B36: 2 | C36: 3 | D36: 1 | E36: 4 | F36: 2 | G36: 3 | H36: 1 | I36: 9 | J36: 2 | K36: 5 | L36: 3 | M36: 2 | N36: 4 | O36: 2 | P36: 3 | Q36: 3 | R36: 4 | S36: 4 | W36: 2 | X36: 4 | Y36: 4 | Z36: 1 | AA36: 3 | AB36: 2 | AD36: 옥천 | AE36: 20
A37: 21 | B37: 2 | C37: 2 | D37: 1 | E37: 8 | F37: 1 | G37: 5 | H37: 3 | I37: 3 | J37: 2 | K37: 4 | L37: 3 | M37: 4 | N37: 2 | O37: 2 | P37: 4 | Q37: 6 | R37: 4 | S37: 2 | T37: 5 | W37: 3 | X37: 3 | Y37: 3 | Z37: 4 | AA37: 5 | AB37: 5 | AD37: 옥천 | AE37: 21
A38: 22 | B38: 1 | C38: 5 | D38: 7 | E38: 7 | F38: 1 | G38: 2 | H38: 1 | I38: 9 | J38: 4 | K38: 1 | L38: 1 | M38: 5 | N38: 5 | O38: 4 | P38: 2 | Q38: 7 | R38: 4 | S38: 3 | T38: 2 | U38: 8 | W38: 3 | X38: 4 | Y38: 4 | Z38: 1 | AA38: 3 | AB38: 5 | AD38: 옥천 | AE38: 22
A39: 23 | B39: 2 | C39: 6 | D39: 1 | E39: 2 | F39: 2 | G39: 5 | H39: 4 | I39: 6 | J39: 2 | K39: 4 | L39: 3 | M39: 1 | N39: 5 | O39: 4 | P39: 1 | Q39: 4 | R39: 4 | S39: 2 | T39: 1 | U39: 3 | W39: 2 | X39: 4 | Y39: 4 | Z39: 1 | AA39: 5 | AB39: 3 | AD39: 옥천 | AE39: 23
A40: 24 | B40: 2 | C40: 3 | D40: 1 | E40: 8 | F40: 2 | G40: 5 | H40: 3 | I40: 2 | J40: 2 | K40: 6 | L40: 4 | M40: 3 | N40: 3 | O40: 3 | P40: 2 | Q40: 5 | R40: 3 | S40: 3 | T40: 3 | U40: 8 | W40: 3 | X40: 3 | Y40: 3 | Z40: 4 | AA40: 2 | AB40: 3 | AD40: 옥천 | AE40: 24
A41: 25 | B41: 2 | C41: 5 | D41: 1 | E41: 8 | F41: 1 | G41: 1 | H41: 1 | I41: 9 | J41: 4 | K41: 4 | L41: 3 | M41: 2 | N41: 5 | O41: 3 | P41: 1 | Q41: 7 | R41: 2 | S41: 3 | T41: 8 | W41: 2 | X41: 3 | Y41: 4 | Z41: 2 | AA41: 2 | AB41: 1 | AD41: 옥천 | AE41: 25
...
